Workbook

Sheet Summary
A1: Features, phases and status - ATIP-DEV, bkesari, bkesari-platform
A2: Status as of 2026-10-09, from the GitHub repositories (sanjaymorankar-debug) and a fresh clone. 'Phases' rolls every feature up by app and phase; the counts are formulas over 'All Features'.
A4: Repositories
A5: Repo | B5: What it is | C5: Default branch | D5: Latest commit | E5: Date | F5: Latest commit message | G5: GitHub
A6: ATIP-DEV | B6: ATIP - AI Trading Intelligence Platform (Python) | C6: master | D6: d01705e | E6: 2026-10-09 | F6: Merge pull request #8: MySQL runtime: translate what cannot translate, quote what MySQL reserves | G6: https://github.com/sanjaymorankar-debug/ATIP-DEV
A7: bkesari | B7: Bkesari shop & milk marketplace (Next.js) | C7: main | D7: 3cfd098 | E7: 2026-10-09 | F7: Merge pull request #13: fill blank test secrets too, so tests pass after cp .env.example .env | G7: https://github.com/sanjaymorankar-debug/bkesari
A8: bkesari-platform | B8: bkesari.com portal + Education (Node / Laravel) | C8: main | D8: 362cbc8 | E8: 2026-10-09 | F8: Merge pull request #4: local MySQL setup script, and the Mac guide and status workbook brought up to date | G8: https://github.com/sanjaymorankar-debug/bkesari-platform
A10: Features by status (from 'All Features')
A11: Repo | B11: Total features | C11: On GitHub default branch | D11: Not merged | E11: Completed | F11: Implemented, not verified | G11: Blocked | H11: In progress | I11: In review (open PR) | J11: In review (draft PR) | K11: Superseded | L11: Not started
A12: ATIP-DEV | B12: =COUNTIF('All Features'!$A$2:$A$423,$A12) -> 337 | C12: =COUNTIFS('All Features'!$A$2:$A$423,$A12,'All Features'!$L$2:$L$423,"Yes") -> 337 | D12: =COUNTIFS('All Features'!$A$2:$A$423,$A12,'All Features'!$L$2:$L$423,"No") -> 0 | E12: =COUNTIFS('All Features'!$A$2:$A$423,$A12,'All Features'!$O$2:$O$423,"COMPLETED") -> 130 | F12: =COUNTIFS('All Features'!$A$2:$A$423,$A12,'All Features'!$O$2:$O$423,"IMPLEMENTED BUT NOT VERIFIED") -> 197 | G12: =COUNTIFS('All Features'!$A$2:$A$423,$A12,'All Features'!$O$2:$O$423,"BLOCKED") -> 9 | H12: =COUNTIFS('All Features'!$A$2:$A$423,$A12,'All Features'!$O$2:$O$423,"IN PROGRESS") -> 1 | I12: =COUNTIFS('All Features'!$A$2:$A$423,$A12,'All Features'!$O$2:$O$423,"IN REVIEW (open PR)") -> 0 | J12: =COUNTIFS('All Features'!$A$2:$A$423,$A12,'All Features'!$O$2:$O$423,"IN REVIEW (draft PR)") -> 0 | K12: =COUNTIFS('All Features'!$A$2:$A$423,$A12,'All Features'!$O$2:$O$423,"SUPERSEDED") -> 0 | L12: =COUNTIFS('All Features'!$A$2:$A$423,$A12,'All Features'!$O$2:$O$423,"NOT STARTED") -> 0
A13: bkesari | B13: =COUNTIF('All Features'!$A$2:$A$423,$A13) -> 33 | C13: =COUNTIFS('All Features'!$A$2:$A$423,$A13,'All Features'!$L$2:$L$423,"Yes") -> 32 | D13: =COUNTIFS('All Features'!$A$2:$A$423,$A13,'All Features'!$L$2:$L$423,"No") -> 1 | E13: =COUNTIFS('All Features'!$A$2:$A$423,$A13,'All Features'!$O$2:$O$423,"COMPLETED") -> 32 | F13: =COUNTIFS('All Features'!$A$2:$A$423,$A13,'All Features'!$O$2:$O$423,"IMPLEMENTED BUT NOT VERIFIED") -> 0 | G13: =COUNTIFS('All Features'!$A$2:$A$423,$A13,'All Features'!$O$2:$O$423,"BLOCKED") -> 0 | H13: =COUNTIFS('All Features'!$A$2:$A$423,$A13,'All Features'!$O$2:$O$423,"IN PROGRESS") -> 0 | I13: =COUNTIFS('All Features'!$A$2:$A$423,$A13,'All Features'!$O$2:$O$423,"IN REVIEW (open PR)") -> 1 | J13: =COUNTIFS('All Features'!$A$2:$A$423,$A13,'All Features'!$O$2:$O$423,"IN REVIEW (draft PR)") -> 0 | K13: =COUNTIFS('All Features'!$A$2:$A$423,$A13,'All Features'!$O$2:$O$423,"SUPERSEDED") -> 0 | L13: =COUNTIFS('All Features'!$A$2:$A$423,$A13,'All Features'!$O$2:$O$423,"NOT STARTED") -> 0
A14: bkesari-platform | B14: =COUNTIF('All Features'!$A$2:$A$423,$A14) -> 52 | C14: =COUNTIFS('All Features'!$A$2:$A$423,$A14,'All Features'!$L$2:$L$423,"Yes") -> 39 | D14: =COUNTIFS('All Features'!$A$2:$A$423,$A14,'All Features'!$L$2:$L$423,"No") -> 13 | E14: =COUNTIFS('All Features'!$A$2:$A$423,$A14,'All Features'!$O$2:$O$423,"COMPLETED") -> 38 | F14: =COUNTIFS('All Features'!$A$2:$A$423,$A14,'All Features'!$O$2:$O$423,"IMPLEMENTED BUT NOT VERIFIED") -> 0 | G14: =COUNTIFS('All Features'!$A$2:$A$423,$A14,'All Features'!$O$2:$O$423,"BLOCKED") -> 0 | H14: =COUNTIFS('All Features'!$A$2:$A$423,$A14,'All Features'!$O$2:$O$423,"IN PROGRESS") -> 0 | I14: =COUNTIFS('All Features'!$A$2:$A$423,$A14,'All Features'!$O$2:$O$423,"IN REVIEW (open PR)") -> 1 | J14: =COUNTIFS('All Features'!$A$2:$A$423,$A14,'All Features'!$O$2:$O$423,"IN REVIEW (draft PR)") -> 0 | K14: =COUNTIFS('All Features'!$A$2:$A$423,$A14,'All Features'!$O$2:$O$423,"SUPERSEDED") -> 1 | L14: =COUNTIFS('All Features'!$A$2:$A$423,$A14,'All Features'!$O$2:$O$423,"NOT STARTED") -> 12
A15: TOTAL | B15: =SUM(B12:B14) -> 422 | C15: =SUM(C12:C14) -> 408 | D15: =SUM(D12:D14) -> 14 | E15: =SUM(E12:E14) -> 200 | F15: =SUM(F12:F14) -> 197 | G15: =SUM(G12:G14) -> 9 | H15: =SUM(H12:H14) -> 1 | I15: =SUM(I12:I14) -> 2 | ... L15: =SUM(L12:L14) -> 12
A16: Check: the status columns add up to 'Total features' | E16: =IF(SUM(E15:L15)=B15,"OK","MISMATCH") -> OK
A18: Pull requests (from 'Pull Requests')
A19: Repo | B19: Total PRs | C19: Merged | D19: Open - not merged | E19: Draft - not merged
A20: ATIP-DEV | B20: =COUNTIF('Pull Requests'!$A$2:$A$28,$A20) -> 8 | C20: =COUNTIFS('Pull Requests'!$A$2:$A$28,$A20,'Pull Requests'!$F$2:$F$28,"Merged") -> 8 | D20: =COUNTIFS('Pull Requests'!$A$2:$A$28,$A20,'Pull Requests'!$F$2:$F$28,"Open - not merged") -> 0 | E20: =COUNTIFS('Pull Requests'!$A$2:$A$28,$A20,'Pull Requests'!$F$2:$F$28,"Draft - not merged") -> 0
A21: bkesari | B21: =COUNTIF('Pull Requests'!$A$2:$A$28,$A21) -> 14 | C21: =COUNTIFS('Pull Requests'!$A$2:$A$28,$A21,'Pull Requests'!$F$2:$F$28,"Merged") -> 13 | D21: =COUNTIFS('Pull Requests'!$A$2:$A$28,$A21,'Pull Requests'!$F$2:$F$28,"Open - not merged") -> 1 | E21: =COUNTIFS('Pull Requests'!$A$2:$A$28,$A21,'Pull Requests'!$F$2:$F$28,"Draft - not merged") -> 0
A22: bkesari-platform | B22: =COUNTIF('Pull Requests'!$A$2:$A$28,$A22) -> 5 | C22: =COUNTIFS('Pull Requests'!$A$2:$A$28,$A22,'Pull Requests'!$F$2:$F$28,"Merged") -> 4 | D22: =COUNTIFS('Pull Requests'!$A$2:$A$28,$A22,'Pull Requests'!$F$2:$F$28,"Open - not merged") -> 1 | E22: =COUNTIFS('Pull Requests'!$A$2:$A$28,$A22,'Pull Requests'!$F$2:$F$28,"Draft - not merged") -> 0
A23: TOTAL | B23: =SUM(B20:B22) -> 27 | C23: =SUM(C20:C22) -> 25 | D23: =SUM(D20:D22) -> 2 | E23: =SUM(E20:E22) -> 0
A25: Branches on GitHub (from 'Branches')
A26: Repo | B26: Branches | C26: Fully merged | D26: Merged (same changes) | E26: NOT merged
A27: ATIP-DEV | B27: =COUNTIF(Branches!$A$2:$A$75,$A27) -> 64 | C27: =COUNTIFS(Branches!$A$2:$A$75,$A27,Branches!$H$2:$H$75,"Fully merged") -> 60 | D27: =COUNTIFS(Branches!$A$2:$A$75,$A27,Branches!$H$2:$H$75,"Merged (same changes already in default)") -> 1 | E27: =COUNTIFS(Branches!$A$2:$A$75,$A27,Branches!$H$2:$H$75,"NOT merged") -> 2
A28: bkesari | B28: =COUNTIF(Branches!$A$2:$A$75,$A28) -> 5 | C28: =COUNTIFS(Branches!$A$2:$A$75,$A28,Branches!$H$2:$H$75,"Fully merged") -> 3 | D28: =COUNTIFS(Branches!$A$2:$A$75,$A28,Branches!$H$2:$H$75,"Merged (same changes already in default)") -> 0 | E28: =COUNTIFS(Branches!$A$2:$A$75,$A28,Branches!$H$2:$H$75,"NOT merged") -> 1
A29: bkesari-platform | B29: =COUNTIF(Branches!$A$2:$A$75,$A29) -> 5 | C29: =COUNTIFS(Branches!$A$2:$A$75,$A29,Branches!$H$2:$H$75,"Fully merged") -> 3 | D29: =COUNTIFS(Branches!$A$2:$A$75,$A29,Branches!$H$2:$H$75,"Merged (same changes already in default)") -> 0 | E29: =COUNTIFS(Branches!$A$2:$A$75,$A29,Branches!$H$2:$H$75,"NOT merged") -> 1
A30: TOTAL | B30: =SUM(B27:B29) -> 74 | C30: =SUM(C27:C29) -> 66 | D30: =SUM(D27:D29) -> 1 | E30: =SUM(E27:E29) -> 4
A32: Read this first
A33: 1. All five PRs that were open on 2026-10-08 (ATIP-DEV#8, bkesari#9 and #10, bkesari-platform#1 and #2) are now merged. bkesari#12, #13 and bkesari-platform#4 followed on 2026-10-09. Open now: bkesari#14 and bkesari-platform#5, both opened on 2026-10-09 by another session (test tooling only).
A34: 2. 'Local Git (fresh clone)' is the clone this report was built from, which matches GitHub. It cannot see commits that exist only on your Mac. Run tools/check_local_git.sh on the Mac to list those (see MAC_DEPLOYMENT.md).
A35: 3. ATIP rows come from the repo's own tracker, docs/ATIP_MASTER_TRACKER.csv (331 rows), plus 6 for the macOS / database PRs. 'IMPLEMENTED BUT NOT VERIFIED' means merged, with automated tests, but independent QA / owner UAT is still pending.
A36: 4. 'Phases' gives one row per phase of each app with its counts, % completed and a phase status. To update a status, change it in the Status column of 'All Features' (it has a drop-down); Phases and this sheet recalculate.
A37: 5. BLOCKED ATIP rows are partly built and wait on an owner decision or credential (see the 'Blocker / next action' column).
A38: 6. The branch claude/epic-brown-iurf1w (this report's own working branch) is left out of 'Branches'.
A39: 7. Testing status: bkesari and Education rows show the result of running their suites on 2026-10-09; ATIP rows keep the tracker's own Testing Status. Every suite passed - see 'Test Runs' (run on Linux, not on a Mac).

Sheet Phases
A1: Features by phase
A2: One row per phase of each app. Every count is a formula over 'All Features', so changing a feature's Status there updates its phase here.
A4: Repo | B4: App | C4: Phase # | D4: Phase | E4: From | F4: To | G4: Features | H4: Completed | I4: Implemented, not verified | J4: Blocked | K4: In progress | L4: In review (PR open) | M4: Not started | N4: Superseded | O4: On GitHub default branch | P4: % completed | Q4: Avg completion % (where recorded) | R4: Phase status
A5: ATIP-DEV | B5: ATIP | C5: 0 | D5: Phase 0: Delivered baseline (maintain) | E5: =IF(COUNTIFS('All Features'!$B$2:$B$423,$B5,'All Features'!$C$2:$C$423,$C5,'All Features'!$J$2:$J$423,">0")=0,"",_xlfn.MINIFS('All Features'!$J$2:$J$423,'All Features'!$B$2:$B$423,$B5,'All Features'!$C$2:$C$423,$C5)) -> 46289 | F5: =IF(COUNTIFS('All Features'!$B$2:$B$423,$B5,'All Features'!$C$2:$C$423,$C5,'All Features'!$J$2:$J$423,">0")=0,"",_xlfn.MAXIFS('All Features'!$J$2:$J$423,'All Features'!$B$2:$B$423,$B5,'All Features'!$C$2:$C$423,$C5)) -> 46302 | G5: =COUNTIFS('All Features'!$B$2:$B$423,$B5,'All Features'!$C$2:$C$423,$C5) -> 58 | H5: =COUNTIFS('All Features'!$B$2:$B$423,$B5,'All Features'!$C$2:$C$423,$C5,'All Features'!$O$2:$O$423,"COMPLETED") -> 58 | I5: =COUNTIFS('All Features'!$B$2:$B$423,$B5,'All Features'!$C$2:$C$423,$C5,'All Features'!$O$2:$O$423,"IMPLEMENTED BUT NOT VERIFIED") -> 0 | J5: =COUNTIFS('All Features'!$B$2:$B$423,$B5,'All Features'!$C$2:$C$423,$C5,'All Features'!$O$2:$O$423,"BLOCKED") -> 0 | K5: =COUNTIFS('All Features'!$B$2:$B$423,$B5,'All Features'!$C$2:$C$423,$C5,'All Features'!$O$2:$O$423,"IN PROGRESS") -> 0 | L5: =COUNTIFS('All Features'!$B$2:$B$423,$B5,'All Features'!$C$2:$C$423,$C5,'All Features'!$O$2:$O$423,"IN REVIEW*") -> 0 | M5: =COUNTIFS('All Features'!$B$2:$B$423,$B5,'All Features'!$C$2:$C$423,$C5,'All Features'!$O$2:$O$423,"NOT STARTED") -> 0 | N5: =COUNTIFS('All Features'!$B$2:$B$423,$B5,'All Features'!$C$2:$C$423,$C5,'All Features'!$O$2:$O$423,"SUPERSEDED") -> 0 | O5: =COUNTIFS('All Features'!$B$2:$B$423,$B5,'All Features'!$C$2:$C$423,$C5,'All Features'!$L$2:$L$423,"Yes") -> 58 | P5: =IFERROR((H5+N5)/G5,0) -> 1 | Q5: =IFERROR(AVERAGEIFS('All Features'!$Q$2:$Q$423,'All Features'!$B$2:$B$423,$B5,'All Features'!$C$2:$C$423,$C5),"") -> 0.79913793 | R5: =IF(G5=0,"-",IF(H5+N5=G5,"COMPLETED",IF(M5=G5,"NOT STARTED",IF(H5+I5+N5=G5,"BUILT - VERIFICATION PENDING","IN PROGRESS"&IF(J5>0," - "&J5&" BLOCKED","")&IF(L5>0," - "&L5&" in review",""))))) -> COMPLETED
A6: ATIP-DEV | B6: ATIP | C6: 1 | D6: Phase 1: Foundation | E6: =IF(COUNTIFS('All Features'!$B$2:$B$423,$B6,'All Features'!$C$2:$C$423,$C6,'All Features'!$J$2:$J$423,">0")=0,"",_xlfn.MINIFS('All Features'!$J$2:$J$423,'All Features'!$B$2:$B$423,$B6,'All Features'!$C$2:$C$423,$C6)) -> 46289 | F6: =IF(COUNTIFS('All Features'!$B$2:$B$423,$B6,'All Features'!$C$2:$C$423,$C6,'All Features'!$J$2:$J$423,">0")=0,"",_xlfn.MAXIFS('All Features'!$J$2:$J$423,'All Features'!$B$2:$B$423,$B6,'All Features'!$C$2:$C$423,$C6)) -> 46302 | G6: =COUNTIFS('All Features'!$B$2:$B$423,$B6,'All Features'!$C$2:$C$423,$C6) -> 31 | H6: =COUNTIFS('All Features'!$B$2:$B$423,$B6,'All Features'!$C$2:$C$423,$C6,'All Features'!$O$2:$O$423,"COMPLETED") -> 27 | I6: =COUNTIFS('All Features'!$B$2:$B$423,$B6,'All Features'!$C$2:$C$423,$C6,'All Features'!$O$2:$O$423,"IMPLEMENTED BUT NOT VERIFIED") -> 4 | J6: =COUNTIFS('All Features'!$B$2:$B$423,$B6,'All Features'!$C$2:$C$423,$C6,'All Features'!$O$2:$O$423,"BLOCKED") -> 0 | K6: =COUNTIFS('All Features'!$B$2:$B$423,$B6,'All Features'!$C$2:$C$423,$C6,'All Features'!$O$2:$O$423,"IN PROGRESS") -> 0 | L6: =COUNTIFS('All Features'!$B$2:$B$423,$B6,'All Features'!$C$2:$C$423,$C6,'All Features'!$O$2:$O$423,"IN REVIEW*") -> 0 | M6: =COUNTIFS('All Features'!$B$2:$B$423,$B6,'All Features'!$C$2:$C$423,$C6,'All Features'!$O$2:$O$423,"NOT STARTED") -> 0 | N6: =COUNTIFS('All Features'!$B$2:$B$423,$B6,'All Features'!$C$2:$C$423,$C6,'All Features'!$O$2:$O$423,"SUPERSEDED") -> 0 | O6: =COUNTIFS('All Features'!$B$2:$B$423,$B6,'All Features'!$C$2:$C$423,$C6,'All Features'!$L$2:$L$423,"Yes") -> 31 | P6: =IFERROR((H6+N6)/G6,0) -> 0.87096774 | Q6: =IFERROR(AVERAGEIFS('All Features'!$Q$2:$Q$423,'All Features'!$B$2:$B$423,$B6,'All Features'!$C$2:$C$423,$C6),"") -> 0.83064516 | R6: =IF(G6=0,"-",IF(H6+N6=G6,"COMPLETED",IF(M6=G6,"NOT STARTED",IF(H6+I6+N6=G6,"BUILT - VERIFICATION PENDING","IN PROGRESS"&IF(J6>0," - "&J6&" BLOCKED","")&IF(L6>0," - "&L6&" in review",""))))) -> BUILT - VERIFICATION PENDING
A7: ATIP-DEV | B7: ATIP | C7: 2 | D7: Phase 2: Quant Research (data, factors, backtesting) | E7: =IF(COUNTIFS('All Features'!$B$2:$B$423,$B7,'All Features'!$C$2:$C$423,$C7,'All Features'!$J$2:$J$423,">0")=0,"",_xlfn.MINIFS('All Features'!$J$2:$J$423,'All Features'!$B$2:$B$423,$B7,'All Features'!$C$2:$C$423,$C7)) -> 46289 | F7: =IF(COUNTIFS('All Features'!$B$2:$B$423,$B7,'All Features'!$C$2:$C$423,$C7,'All Features'!$J$2:$J$423,">0")=0,"",_xlfn.MAXIFS('All Features'!$J$2:$J$423,'All Features'!$B$2:$B$423,$B7,'All Features'!$C$2:$C$423,$C7)) -> 46302 | G7: =COUNTIFS('All Features'!$B$2:$B$423,$B7,'All Features'!$C$2:$C$423,$C7) -> 52 | H7: =COUNTIFS('All Features'!$B$2:$B$423,$B7,'All Features'!$C$2:$C$423,$C7,'All Features'!$O$2:$O$423,"COMPLETED") -> 17 | I7: =COUNTIFS('All Features'!$B$2:$B$423,$B7,'All Features'!$C$2:$C$423,$C7,'All Features'!$O$2:$O$423,"IMPLEMENTED BUT NOT VERIFIED") -> 35 | J7: =COUNTIFS('All Features'!$B$2:$B$423,$B7,'All Features'!$C$2:$C$423,$C7,'All Features'!$O$2:$O$423,"BLOCKED") -> 0 | K7: =COUNTIFS('All Features'!$B$2:$B$423,$B7,'All Features'!$C$2:$C$423,$C7,'All Features'!$O$2:$O$423,"IN PROGRESS") -> 0 | L7: =COUNTIFS('All Features'!$B$2:$B$423,$B7,'All Features'!$C$2:$C$423,$C7,'All Features'!$O$2:$O$423,"IN REVIEW*") -> 0 | M7: =COUNTIFS('All Features'!$B$2:$B$423,$B7,'All Features'!$C$2:$C$423,$C7,'All Features'!$O$2:$O$423,"NOT STARTED") -> 0 | N7: =COUNTIFS('All Features'!$B$2:$B$423,$B7,'All Features'!$C$2:$C$423,$C7,'All Features'!$O$2:$O$423,"SUPERSEDED") -> 0 | O7: =COUNTIFS('All Features'!$B$2:$B$423,$B7,'All Features'!$C$2:$C$423,$C7,'All Features'!$L$2:$L$423,"Yes") -> 52 | P7: =IFERROR((H7+N7)/G7,0) -> 0.32692308 | Q7: =IFERROR(AVERAGEIFS('All Features'!$Q$2:$Q$423,'All Features'!$B$2:$B$423,$B7,'All Features'!$C$2:$C$423,$C7),"") -> 0.80673077 | R7: =IF(G7=0,"-",IF(H7+N7=G7,"COMPLETED",IF(M7=G7,"NOT STARTED",IF(H7+I7+N7=G7,"BUILT - VERIFICATION PENDING","IN PROGRESS"&IF(J7>0," - "&J7&" BLOCKED","")&IF(L7>0," - "&L7&" in review",""))))) -> BUILT - VERIFICATION PENDING
A8: ATIP-DEV | B8: ATIP | C8: 3 | D8: Phase 3: Strategy Engine | E8: =IF(COUNTIFS('All Features'!$B$2:$B$423,$B8,'All Features'!$C$2:$C$423,$C8,'All Features'!$J$2:$J$423,">0")=0,"",_xlfn.MINIFS('All Features'!$J$2:$J$423,'All Features'!$B$2:$B$423,$B8,'All Features'!$C$2:$C$423,$C8)) -> 46289 | F8: =IF(COUNTIFS('All Features'!$B$2:$B$423,$B8,'All Features'!$C$2:$C$423,$C8,'All Features'!$J$2:$J$423,">0")=0,"",_xlfn.MAXIFS('All Features'!$J$2:$J$423,'All Features'!$B$2:$B$423,$B8,'All Features'!$C$2:$C$423,$C8)) -> 46302 | G8: =COUNTIFS('All Features'!$B$2:$B$423,$B8,'All Features'!$C$2:$C$423,$C8) -> 14 | H8: =COUNTIFS('All Features'!$B$2:$B$423,$B8,'All Features'!$C$2:$C$423,$C8,'All Features'!$O$2:$O$423,"COMPLETED") -> 11 | I8: =COUNTIFS('All Features'!$B$2:$B$423,$B8,'All Features'!$C$2:$C$423,$C8,'All Features'!$O$2:$O$423,"IMPLEMENTED BUT NOT VERIFIED") -> 3 | J8: =COUNTIFS('All Features'!$B$2:$B$423,$B8,'All Features'!$C$2:$C$423,$C8,'All Features'!$O$2:$O$423,"BLOCKED") -> 0 | K8: =COUNTIFS('All Features'!$B$2:$B$423,$B8,'All Features'!$C$2:$C$423,$C8,'All Features'!$O$2:$O$423,"IN PROGRESS") -> 0 | L8: =COUNTIFS('All Features'!$B$2:$B$423,$B8,'All Features'!$C$2:$C$423,$C8,'All Features'!$O$2:$O$423,"IN REVIEW*") -> 0 | M8: =COUNTIFS('All Features'!$B$2:$B$423,$B8,'All Features'!$C$2:$C$423,$C8,'All Features'!$O$2:$O$423,"NOT STARTED") -> 0 | N8: =COUNTIFS('All Features'!$B$2:$B$423,$B8,'All Features'!$C$2:$C$423,$C8,'All Features'!$O$2:$O$423,"SUPERSEDED") -> 0 | O8: =COUNTIFS('All Features'!$B$2:$B$423,$B8,'All Features'!$C$2:$C$423,$C8,'All Features'!$L$2:$L$423,"Yes") -> 14 | P8: =IFERROR((H8+N8)/G8,0) -> 0.78571429 | Q8: =IFERROR(AVERAGEIFS('All Features'!$Q$2:$Q$423,'All Features'!$B$2:$B$423,$B8,'All Features'!$C$2:$C$423,$C8),"") -> 0.80357143 | R8: =IF(G8=0,"-",IF(H8+N8=G8,"COMPLETED",IF(M8=G8,"NOT STARTED",IF(H8+I8+N8=G8,"BUILT - VERIFICATION PENDING","IN PROGRESS"&IF(J8>0," - "&J8&" BLOCKED","")&IF(L8>0," - "&L8&" in review",""))))) -> BUILT - VERIFICATION PENDING
A9: ATIP-DEV | B9: ATIP | C9: 4 | D9: Phase 4: AI/ML | E9: =IF(COUNTIFS('All Features'!$B$2:$B$423,$B9,'All Features'!$C$2:$C$423,$C9,'All Features'!$J$2:$J$423,">0")=0,"",_xlfn.MINIFS('All Features'!$J$2:$J$423,'All Features'!$B$2:$B$423,$B9,'All Features'!$C$2:$C$423,$C9)) -> 46290 | F9: =IF(COUNTIFS('All Features'!$B$2:$B$423,$B9,'All Features'!$C$2:$C$423,$C9,'All Features'!$J$2:$J$423,">0")=0,"",_xlfn.MAXIFS('All Features'!$J$2:$J$423,'All Features'!$B$2:$B$423,$B9,'All Features'!$C$2:$C$423,$C9)) -> 46302 | G9: =COUNTIFS('All Features'!$B$2:$B$423,$B9,'All Features'!$C$2:$C$423,$C9) -> 21 | H9: =COUNTIFS('All Features'!$B$2:$B$423,$B9,'All Features'!$C$2:$C$423,$C9,'All Features'!$O$2:$O$423,"COMPLETED") -> 2 | I9: =COUNTIFS('All Features'!$B$2:$B$423,$B9,'All Features'!$C$2:$C$423,$C9,'All Features'!$O$2:$O$423,"IMPLEMENTED BUT NOT VERIFIED") -> 18 | J9: =COUNTIFS('All Features'!$B$2:$B$423,$B9,'All Features'!$C$2:$C$423,$C9,'All Features'!$O$2:$O$423,"BLOCKED") -> 1 | K9: =COUNTIFS('All Features'!$B$2:$B$423,$B9,'All Features'!$C$2:$C$423,$C9,'All Features'!$O$2:$O$423,"IN PROGRESS") -> 0 | L9: =COUNTIFS('All Features'!$B$2:$B$423,$B9,'All Features'!$C$2:$C$423,$C9,'All Features'!$O$2:$O$423,"IN REVIEW*") -> 0 | M9: =COUNTIFS('All Features'!$B$2:$B$423,$B9,'All Features'!$C$2:$C$423,$C9,'All Features'!$O$2:$O$423,"NOT STARTED") -> 0 | N9: =COUNTIFS('All Features'!$B$2:$B$423,$B9,'All Features'!$C$2:$C$423,$C9,'All Features'!$O$2:$O$423,"SUPERSEDED") -> 0 | O9: =COUNTIFS('All Features'!$B$2:$B$423,$B9,'All Features'!$C$2:$C$423,$C9,'All Features'!$L$2:$L$423,"Yes") -> 21 | P9: =IFERROR((H9+N9)/G9,0) -> 0.095238095 | Q9: =IFERROR(AVERAGEIFS('All Features'!$Q$2:$Q$423,'All Features'!$B$2:$B$423,$B9,'All Features'!$C$2:$C$423,$C9),"") -> 0.79761905 | R9: =IF(G9=0,"-",IF(H9+N9=G9,"COMPLETED",IF(M9=G9,"NOT STARTED",IF(H9+I9+N9=G9,"BUILT - VERIFICATION PENDING","IN PROGRESS"&IF(J9>0," - "&J9&" BLOCKED","")&IF(L9>0," - "&L9&" in review",""))))) -> IN PROGRESS - 1 BLOCKED
A10: ATIP-DEV | B10: ATIP | C10: 5 | D10: Phase 5: Risk & Portfolio | E10: =IF(COUNTIFS('All Features'!$B$2:$B$423,$B10,'All Features'!$C$2:$C$423,$C10,'All Features'!$J$2:$J$423,">0")=0,"",_xlfn.MINIFS('All Features'!$J$2:$J$423,'All Features'!$B$2:$B$423,$B10,'All Features'!$C$2:$C$423,$C10)) -> 46289 | F10: =IF(COUNTIFS('All Features'!$B$2:$B$423,$B10,'All Features'!$C$2:$C$423,$C10,'All Features'!$J$2:$J$423,">0")=0,"",_xlfn.MAXIFS('All Features'!$J$2:$J$423,'All Features'!$B$2:$B$423,$B10,'All Features'!$C$2:$C$423,$C10)) -> 46302 | G10: =COUNTIFS('All Features'!$B$2:$B$423,$B10,'All Features'!$C$2:$C$423,$C10) -> 17 | H10: =COUNTIFS('All Features'!$B$2:$B$423,$B10,'All Features'!$C$2:$C$423,$C10,'All Features'!$O$2:$O$423,"COMPLETED") -> 3 | I10: =COUNTIFS('All Features'!$B$2:$B$423,$B10,'All Features'!$C$2:$C$423,$C10,'All Features'!$O$2:$O$423,"IMPLEMENTED BUT NOT VERIFIED") -> 14 | J10: =COUNTIFS('All Features'!$B$2:$B$423,$B10,'All Features'!$C$2:$C$423,$C10,'All Features'!$O$2:$O$423,"BLOCKED") -> 0 | K10: =COUNTIFS('All Features'!$B$2:$B$423,$B10,'All Features'!$C$2:$C$423,$C10,'All Features'!$O$2:$O$423,"IN PROGRESS") -> 0 | L10: =COUNTIFS('All Features'!$B$2:$B$423,$B10,'All Features'!$C$2:$C$423,$C10,'All Features'!$O$2:$O$423,"IN REVIEW*") -> 0 | M10: =COUNTIFS('All Features'!$B$2:$B$423,$B10,'All Features'!$C$2:$C$423,$C10,'All Features'!$O$2:$O$423,"NOT STARTED") -> 0 | N10: =COUNTIFS('All Features'!$B$2:$B$423,$B10,'All Features'!$C$2:$C$423,$C10,'All Features'!$O$2:$O$423,"SUPERSEDED") -> 0 | O10: =COUNTIFS('All Features'!$B$2:$B$423,$B10,'All Features'!$C$2:$C$423,$C10,'All Features'!$L$2:$L$423,"Yes") -> 17 | P10: =IFERROR((H10+N10)/G10,0) -> 0.17647059 | Q10: =IFERROR(AVERAGEIFS('All Features'!$Q$2:$Q$423,'All Features'!$B$2:$B$423,$B10,'All Features'!$C$2:$C$423,$C10),"") -> 0.83529412 | R10: =IF(G10=0,"-",IF(H10+N10=G10,"COMPLETED",IF(M10=G10,"NOT STARTED",IF(H10+I10+N10=G10,"BUILT - VERIFICATION PENDING","IN PROGRESS"&IF(J10>0," - "&J10&" BLOCKED","")&IF(L10>0," - "&L10&" in review",""))))) -> BUILT - VERIFICATION PENDING
A11: ATIP-DEV | B11: ATIP | C11: 6 | D11: Phase 6: Execution | E11: =IF(COUNTIFS('All Features'!$B$2:$B$423,$B11,'All Features'!$C$2:$C$423,$C11,'All Features'!$J$2:$J$423,">0")=0,"",_xlfn.MINIFS('All Features'!$J$2:$J$423,'All Features'!$B$2:$B$423,$B11,'All Features'!$C$2:$C$423,$C11)) -> 46296 | F11: =IF(COUNTIFS('All Features'!$B$2:$B$423,$B11,'All Features'!$C$2:$C$423,$C11,'All Features'!$J$2:$J$423,">0")=0,"",_xlfn.MAXIFS('All Features'!$J$2:$J$423,'All Features'!$B$2:$B$423,$B11,'All Features'!$C$2:$C$423,$C11)) -> 46302 | G11: =COUNTIFS('All Features'!$B$2:$B$423,$B11,'All Features'!$C$2:$C$423,$C11) -> 11 | H11: =COUNTIFS('All Features'!$B$2:$B$423,$B11,'All Features'!$C$2:$C$423,$C11,'All Features'!$O$2:$O$423,"COMPLETED") -> 0 | I11: =COUNTIFS('All Features'!$B$2:$B$423,$B11,'All Features'!$C$2:$C$423,$C11,'All Features'!$O$2:$O$423,"IMPLEMENTED BUT NOT VERIFIED") -> 10 | J11: =COUNTIFS('All Features'!$B$2:$B$423,$B11,'All Features'!$C$2:$C$423,$C11,'All Features'!$O$2:$O$423,"BLOCKED") -> 1 | K11: =COUNTIFS('All Features'!$B$2:$B$423,$B11,'All Features'!$C$2:$C$423,$C11,'All Features'!$O$2:$O$423,"IN PROGRESS") -> 0 | L11: =COUNTIFS('All Features'!$B$2:$B$423,$B11,'All Features'!$C$2:$C$423,$C11,'All Features'!$O$2:$O$423,"IN REVIEW*") -> 0 | M11: =COUNTIFS('All Features'!$B$2:$B$423,$B11,'All Features'!$C$2:$C$423,$C11,'All Features'!$O$2:$O$423,"NOT STARTED") -> 0 | N11: =COUNTIFS('All Features'!$B$2:$B$423,$B11,'All Features'!$C$2:$C$423,$C11,'All Features'!$O$2:$O$423,"SUPERSEDED") -> 0 | O11: =COUNTIFS('All Features'!$B$2:$B$423,$B11,'All Features'!$C$2:$C$423,$C11,'All Features'!$L$2:$L$423,"Yes") -> 11 | P11: =IFERROR((H11+N11)/G11,0) -> 0 | Q11: =IFERROR(AVERAGEIFS('All Features'!$Q$2:$Q$423,'All Features'!$B$2:$B$423,$B11,'All Features'!$C$2:$C$423,$C11),"") -> 0.83636364 | R11: =IF(G11=0,"-",IF(H11+N11=G11,"COMPLETED",IF(M11=G11,"NOT STARTED",IF(H11+I11+N11=G11,"BUILT - VERIFICATION PENDING","IN PROGRESS"&IF(J11>0," - "&J11&" BLOCKED","")&IF(L11>0," - "&L11&" in review",""))))) -> IN PROGRESS - 1 BLOCKED
A12: ATIP-DEV | B12: ATIP | C12: 7 | D12: Phase 7: Advanced Quant | E12: =IF(COUNTIFS('All Features'!$B$2:$B$423,$B12,'All Features'!$C$2:$C$423,$C12,'All Features'!$J$2:$J$423,">0")=0,"",_xlfn.MINIFS('All Features'!$J$2:$J$423,'All Features'!$B$2:$B$423,$B12,'All Features'!$C$2:$C$423,$C12)) -> 46296 | F12: =IF(COUNTIFS('All Features'!$B$2:$B$423,$B12,'All Features'!$C$2:$C$423,$C12,'All Features'!$J$2:$J$423,">0")=0,"",_xlfn.MAXIFS('All Features'!$J$2:$J$423,'All Features'!$B$2:$B$423,$B12,'All Features'!$C$2:$C$423,$C12)) -> 46302 | G12: =COUNTIFS('All Features'!$B$2:$B$423,$B12,'All Features'!$C$2:$C$423,$C12) -> 19 | H12: =COUNTIFS('All Features'!$B$2:$B$423,$B12,'All Features'!$C$2:$C$423,$C12,'All Features'!$O$2:$O$423,"COMPLETED") -> 0 | I12: =COUNTIFS('All Features'!$B$2:$B$423,$B12,'All Features'!$C$2:$C$423,$C12,'All Features'!$O$2:$O$423,"IMPLEMENTED BUT NOT VERIFIED") -> 19 | J12: =COUNTIFS('All Features'!$B$2:$B$423,$B12,'All Features'!$C$2:$C$423,$C12,'All Features'!$O$2:$O$423,"BLOCKED") -> 0 | K12: =COUNTIFS('All Features'!$B$2:$B$423,$B12,'All Features'!$C$2:$C$423,$C12,'All Features'!$O$2:$O$423,"IN PROGRESS") -> 0 | L12: =COUNTIFS('All Features'!$B$2:$B$423,$B12,'All Features'!$C$2:$C$423,$C12,'All Features'!$O$2:$O$423,"IN REVIEW*") -> 0 | M12: =COUNTIFS('All Features'!$B$2:$B$423,$B12,'All Features'!$C$2:$C$423,$C12,'All Features'!$O$2:$O$423,"NOT STARTED") -> 0 | N12: =COUNTIFS('All Features'!$B$2:$B$423,$B12,'All Features'!$C$2:$C$423,$C12,'All Features'!$O$2:$O$423,"SUPERSEDED") -> 0 | O12: =COUNTIFS('All Features'!$B$2:$B$423,$B12,'All Features'!$C$2:$C$423,$C12,'All Features'!$L$2:$L$423,"Yes") -> 19 | P12: =IFERROR((H12+N12)/G12,0) -> 0 | Q12: =IFERROR(AVERAGEIFS('All Features'!$Q$2:$Q$423,'All Features'!$B$2:$B$423,$B12,'All Features'!$C$2:$C$423,$C12),"") -> 0.78684211 | R12: =IF(G12=0,"-",IF(H12+N12=G12,"COMPLETED",IF(M12=G12,"NOT STARTED",IF(H12+I12+N12=G12,"BUILT - VERIFICATION PENDING","IN PROGRESS"&IF(J12>0," - "&J12&" BLOCKED","")&IF(L12>0," - "&L12&" in review",""))))) -> BUILT - VERIFICATION PENDING
A13: ATIP-DEV | B13: ATIP | C13: 8 | D13: Phase 8: Production hardening | E13: =IF(COUNTIFS('All Features'!$B$2:$B$423,$B13,'All Features'!$C$2:$C$423,$C13,'All Features'!$J$2:$J$423,">0")=0,"",_xlfn.MINIFS('All Features'!$J$2:$J$423,'All Features'!$B$2:$B$423,$B13,'All Features'!$C$2:$C$423,$C13)) -> 46290 | F13: =IF(COUNTIFS('All Features'!$B$2:$B$423,$B13,'All Features'!$C$2:$C$423,$C13,'All Features'!$J$2:$J$423,">0")=0,"",_xlfn.MAXIFS('All Features'!$J$2:$J$423,'All Features'!$B$2:$B$423,$B13,'All Features'!$C$2:$C$423,$C13)) -> 46302 | G13: =COUNTIFS('All Features'!$B$2:$B$423,$B13,'All Features'!$C$2:$C$423,$C13) -> 14 | H13: =COUNTIFS('All Features'!$B$2:$B$423,$B13,'All Features'!$C$2:$C$423,$C13,'All Features'!$O$2:$O$423,"COMPLETED") -> 6 | I13: =COUNTIFS('All Features'!$B$2:$B$423,$B13,'All Features'!$C$2:$C$423,$C13,'All Features'!$O$2:$O$423,"IMPLEMENTED BUT NOT VERIFIED") -> 8 | J13: =COUNTIFS('All Features'!$B$2:$B$423,$B13,'All Features'!$C$2:$C$423,$C13,'All Features'!$O$2:$O$423,"BLOCKED") -> 0 | K13: =COUNTIFS('All Features'!$B$2:$B$423,$B13,'All Features'!$C$2:$C$423,$C13,'All Features'!$O$2:$O$423,"IN PROGRESS") -> 0 | L13: =COUNTIFS('All Features'!$B$2:$B$423,$B13,'All Features'!$C$2:$C$423,$C13,'All Features'!$O$2:$O$423,"IN REVIEW*") -> 0 | M13: =COUNTIFS('All Features'!$B$2:$B$423,$B13,'All Features'!$C$2:$C$423,$C13,'All Features'!$O$2:$O$423,"NOT STARTED") -> 0 | N13: =COUNTIFS('All Features'!$B$2:$B$423,$B13,'All Features'!$C$2:$C$423,$C13,'All Features'!$O$2:$O$423,"SUPERSEDED") -> 0 | O13: =COUNTIFS('All Features'!$B$2:$B$423,$B13,'All Features'!$C$2:$C$423,$C13,'All Features'!$L$2:$L$423,"Yes") -> 14 | P13: =IFERROR((H13+N13)/G13,0) -> 0.42857143 | Q13: =IFERROR(AVERAGEIFS('All Features'!$Q$2:$Q$423,'All Features'!$B$2:$B$423,$B13,'All Features'!$C$2:$C$423,$C13),"") -> 0.84642857 | R13: =IF(G13=0,"-",IF(H13+N13=G13,"COMPLETED",IF(M13=G13,"NOT STARTED",IF(H13+I13+N13=G13,"BUILT - VERIFICATION PENDING","IN PROGRESS"&IF(J13>0," - "&J13&" BLOCKED","")&IF(L13>0," - "&L13&" in review",""))))) -> BUILT - VERIFICATION PENDING
A14: ATIP-DEV | B14: ATIP | C14: 9 | D14: Phase 9: Enterprise SaaS (final objective) | E14: =IF(COUNTIFS('All Features'!$B$2:$B$423,$B14,'All Features'!$C$2:$C$423,$C14,'All Features'!$J$2:$J$423,">0")=0,"",_xlfn.MINIFS('All Features'!$J$2:$J$423,'All Features'!$B$2:$B$423,$B14,'All Features'!$C$2:$C$423,$C14)) -> 46290 | F14: =IF(COUNTIFS('All Features'!$B$2:$B$423,$B14,'All Features'!$C$2:$C$423,$C14,'All Features'!$J$2:$J$423,">0")=0,"",_xlfn.MAXIFS('All Features'!$J$2:$J$423,'All Features'!$B$2:$B$423,$B14,'All Features'!$C$2:$C$423,$C14)) -> 46302 | G14: =COUNTIFS('All Features'!$B$2:$B$423,$B14,'All Features'!$C$2:$C$423,$C14) -> 29 | H14: =COUNTIFS('All Features'!$B$2:$B$423,$B14,'All Features'!$C$2:$C$423,$C14,'All Features'!$O$2:$O$423,"COMPLETED") -> 2 | I14: =COUNTIFS('All Features'!$B$2:$B$423,$B14,'All Features'!$C$2:$C$423,$C14,'All Features'!$O$2:$O$423,"IMPLEMENTED BUT NOT VERIFIED") -> 22 | J14: =COUNTIFS('All Features'!$B$2:$B$423,$B14,'All Features'!$C$2:$C$423,$C14,'All Features'!$O$2:$O$423,"BLOCKED") -> 5 | K14: =COUNTIFS('All Features'!$B$2:$B$423,$B14,'All Features'!$C$2:$C$423,$C14,'All Features'!$O$2:$O$423,"IN PROGRESS") -> 0 | L14: =COUNTIFS('All Features'!$B$2:$B$423,$B14,'All Features'!$C$2:$C$423,$C14,'All Features'!$O$2:$O$423,"IN REVIEW*") -> 0 | M14: =COUNTIFS('All Features'!$B$2:$B$423,$B14,'All Features'!$C$2:$C$423,$C14,'All Features'!$O$2:$O$423,"NOT STARTED") -> 0 | N14: =COUNTIFS('All Features'!$B$2:$B$423,$B14,'All Features'!$C$2:$C$423,$C14,'All Features'!$O$2:$O$423,"SUPERSEDED") -> 0 | O14: =COUNTIFS('All Features'!$B$2:$B$423,$B14,'All Features'!$C$2:$C$423,$C14,'All Features'!$L$2:$L$423,"Yes") -> 29 | P14: =IFERROR((H14+N14)/G14,0) -> 0.068965517 | Q14: =IFERROR(AVERAGEIFS('All Features'!$Q$2:$Q$423,'All Features'!$B$2:$B$423,$B14,'All Features'!$C$2:$C$423,$C14),"") -> 0.7362069 | R14: =IF(G14=0,"-",IF(H14+N14=G14,"COMPLETED",IF(M14=G14,"NOT STARTED",IF(H14+I14+N14=G14,"BUILT - VERIFICATION PENDING","IN PROGRESS"&IF(J14>0," - "&J14&" BLOCKED","")&IF(L14>0," - "&L14&" in review",""))))) -> IN PROGRESS - 5 BLOCKED
A15: ATIP-DEV | B15: ATIP | C15: 10 | D15: Phase 10: Wealth track (Waves 11-20) | E15: =IF(COUNTIFS('All Features'!$B$2:$B$423,$B15,'All Features'!$C$2:$C$423,$C15,'All Features'!$J$2:$J$423,">0")=0,"",_xlfn.MINIFS('All Features'!$J$2:$J$423,'All Features'!$B$2:$B$423,$B15,'All Features'!$C$2:$C$423,$C15)) -> 46291 | F15: =IF(COUNTIFS('All Features'!$B$2:$B$423,$B15,'All Features'!$C$2:$C$423,$C15,'All Features'!$J$2:$J$423,">0")=0,"",_xlfn.MAXIFS('All Features'!$J$2:$J$423,'All Features'!$B$2:$B$423,$B15,'All Features'!$C$2:$C$423,$C15)) -> 46302 | G15: =COUNTIFS('All Features'!$B$2:$B$423,$B15,'All Features'!$C$2:$C$423,$C15) -> 11 | H15: =COUNTIFS('All Features'!$B$2:$B$423,$B15,'All Features'!$C$2:$C$423,$C15,'All Features'!$O$2:$O$423,"COMPLETED") -> 0 | I15: =COUNTIFS('All Features'!$B$2:$B$423,$B15,'All Features'!$C$2:$C$423,$C15,'All Features'!$O$2:$O$423,"IMPLEMENTED BUT NOT VERIFIED") -> 9 | J15: =COUNTIFS('All Features'!$B$2:$B$423,$B15,'All Features'!$C$2:$C$423,$C15,'All Features'!$O$2:$O$423,"BLOCKED") -> 1 | K15: =COUNTIFS('All Features'!$B$2:$B$423,$B15,'All Features'!$C$2:$C$423,$C15,'All Features'!$O$2:$O$423,"IN PROGRESS") -> 1 | L15: =COUNTIFS('All Features'!$B$2:$B$423,$B15,'All Features'!$C$2:$C$423,$C15,'All Features'!$O$2:$O$423,"IN REVIEW*") -> 0 | M15: =COUNTIFS('All Features'!$B$2:$B$423,$B15,'All Features'!$C$2:$C$423,$C15,'All Features'!$O$2:$O$423,"NOT STARTED") -> 0 | N15: =COUNTIFS('All Features'!$B$2:$B$423,$B15,'All Features'!$C$2:$C$423,$C15,'All Features'!$O$2:$O$423,"SUPERSEDED") -> 0 | O15: =COUNTIFS('All Features'!$B$2:$B$423,$B15,'All Features'!$C$2:$C$423,$C15,'All Features'!$L$2:$L$423,"Yes") -> 11 | P15: =IFERROR((H15+N15)/G15,0) -> 0 | Q15: =IFERROR(AVERAGEIFS('All Features'!$Q$2:$Q$423,'All Features'!$B$2:$B$423,$B15,'All Features'!$C$2:$C$423,$C15),"") -> 0.80454545 | R15: =IF(G15=0,"-",IF(H15+N15=G15,"COMPLETED",IF(M15=G15,"NOT STARTED",IF(H15+I15+N15=G15,"BUILT - VERIFICATION PENDING","IN PROGRESS"&IF(J15>0," - "&J15&" BLOCKED","")&IF(L15>0," - "&L15&" in review",""))))) -> IN PROGRESS - 1 BLOCKED
A16: ATIP-DEV | B16: ATIP | C16: 11 | D16: Phase 11: W39 reconciliation (owner tracker 2026-10-07) | E16: =IF(COUNTIFS('All Features'!$B$2:$B$423,$B16,'All Features'!$C$2:$C$423,$C16,'All Features'!$J$2:$J$423,">0")=0,"",_xlfn.MINIFS('All Features'!$J$2:$J$423,'All Features'!$B$2:$B$423,$B16,'All Features'!$C$2:$C$423,$C16)) -> 46302 | F16: =IF(COUNTIFS('All Features'!$B$2:$B$423,$B16,'All Features'!$C$2:$C$423,$C16,'All Features'!$J$2:$J$423,">0")=0,"",_xlfn.MAXIFS('All Features'!$J$2:$J$423,'All Features'!$B$2:$B$423,$B16,'All Features'!$C$2:$C$423,$C16)) -> 46302 | G16: =COUNTIFS('All Features'!$B$2:$B$423,$B16,'All Features'!$C$2:$C$423,$C16) -> 54 | H16: =COUNTIFS('All Features'!$B$2:$B$423,$B16,'All Features'!$C$2:$C$423,$C16,'All Features'!$O$2:$O$423,"COMPLETED") -> 0 | I16: =COUNTIFS('All Features'!$B$2:$B$423,$B16,'All Features'!$C$2:$C$423,$C16,'All Features'!$O$2:$O$423,"IMPLEMENTED BUT NOT VERIFIED") -> 53 | J16: =COUNTIFS('All Features'!$B$2:$B$423,$B16,'All Features'!$C$2:$C$423,$C16,'All Features'!$O$2:$O$423,"BLOCKED") -> 1 | K16: =COUNTIFS('All Features'!$B$2:$B$423,$B16,'All Features'!$C$2:$C$423,$C16,'All Features'!$O$2:$O$423,"IN PROGRESS") -> 0 | L16: =COUNTIFS('All Features'!$B$2:$B$423,$B16,'All Features'!$C$2:$C$423,$C16,'All Features'!$O$2:$O$423,"IN REVIEW*") -> 0 | M16: =COUNTIFS('All Features'!$B$2:$B$423,$B16,'All Features'!$C$2:$C$423,$C16,'All Features'!$O$2:$O$423,"NOT STARTED") -> 0 | N16: =COUNTIFS('All Features'!$B$2:$B$423,$B16,'All Features'!$C$2:$C$423,$C16,'All Features'!$O$2:$O$423,"SUPERSEDED") -> 0 | O16: =COUNTIFS('All Features'!$B$2:$B$423,$B16,'All Features'!$C$2:$C$423,$C16,'All Features'!$L$2:$L$423,"Yes") -> 54 | P16: =IFERROR((H16+N16)/G16,0) -> 0 | Q16: =IFERROR(AVERAGEIFS('All Features'!$Q$2:$Q$423,'All Features'!$B$2:$B$423,$B16,'All Features'!$C$2:$C$423,$C16),"") -> 0.84722222 | R16: =IF(G16=0,"-",IF(H16+N16=G16,"COMPLETED",IF(M16=G16,"NOT STARTED",IF(H16+I16+N16=G16,"BUILT - VERIFICATION PENDING","IN PROGRESS"&IF(J16>0," - "&J16&" BLOCKED","")&IF(L16>0," - "&L16&" in review",""))))) -> IN PROGRESS - 1 BLOCKED
... A37: bkesari-platform | B37: Education | C37: 10 | D37: Phase 10: Multilingual (on hold for translators) | E37: =IF(COUNTIFS('All Features'!$B$2:$B$423,$B37,'All Features'!$C$2:$C$423,$C37,'All Features'!$J$2:$J$423,">0")=0,"",_xlfn.MINIFS('All Features'!$J$2:$J$423,'All Features'!$B$2:$B$423,$B37,'All Features'!$C$2:$C$423,$C37)) | F37: =IF(COUNTIFS('All Features'!$B$2:$B$423,$B37,'All Features'!$C$2:$C$423,$C37,'All Features'!$J$2:$J$423,">0")=0,"",_xlfn.MAXIFS('All Features'!$J$2:$J$423,'All Features'!$B$2:$B$423,$B37,'All Features'!$C$2:$C$423,$C37)) | G37: =COUNTIFS('All Features'!$B$2:$B$423,$B37,'All Features'!$C$2:$C$423,$C37) -> 1 | H37: =COUNTIFS('All Features'!$B$2:$B$423,$B37,'All Features'!$C$2:$C$423,$C37,'All Features'!$O$2:$O$423,"COMPLETED") -> 0 | I37: =COUNTIFS('All Features'!$B$2:$B$423,$B37,'All Features'!$C$2:$C$423,$C37,'All Features'!$O$2:$O$423,"IMPLEMENTED BUT NOT VERIFIED") -> 0 | J37: =COUNTIFS('All Features'!$B$2:$B$423,$B37,'All Features'!$C$2:$C$423,$C37,'All Features'!$O$2:$O$423,"BLOCKED") -> 0 | K37: =COUNTIFS('All Features'!$B$2:$B$423,$B37,'All Features'!$C$2:$C$423,$C37,'All Features'!$O$2:$O$423,"IN PROGRESS") -> 0 | L37: =COUNTIFS('All Features'!$B$2:$B$423,$B37,'All Features'!$C$2:$C$423,$C37,'All Features'!$O$2:$O$423,"IN REVIEW*") -> 0 | M37: =COUNTIFS('All Features'!$B$2:$B$423,$B37,'All Features'!$C$2:$C$423,$C37,'All Features'!$O$2:$O$423,"NOT STARTED") -> 1 | N37: =COUNTIFS('All Features'!$B$2:$B$423,$B37,'All Features'!$C$2:$C$423,$C37,'All Features'!$O$2:$O$423,"SUPERSEDED") -> 0 | O37: =COUNTIFS('All Features'!$B$2:$B$423,$B37,'All Features'!$C$2:$C$423,$C37,'All Features'!$L$2:$L$423,"Yes") -> 0 | P37: =IFERROR((H37+N37)/G37,0) -> 0 | Q37: =IFERROR(AVERAGEIFS('All Features'!$Q$2:$Q$423,'All Features'!$B$2:$B$423,$B37,'All Features'!$C$2:$C$423,$C37),"") -> 0 | R37: =IF(G37=0,"-",IF(H37+N37=G37,"COMPLETED",IF(M37=G37,"NOT STARTED",IF(H37+I37+N37=G37,"BUILT - VERIFICATION PENDING","IN PROGRESS"&IF(J37>0," - "&J37&" BLOCKED","")&IF(L37>0," - "&L37&" in review",""))))) -> NOT STARTED
A39: Totals per app
A40: Repo | B40: App | C40: Phases | G40: Features | H40: Completed | I40: Implemented, not verified | J40: Blocked | K40: In progress | L40: In review (PR open) | M40: Not started | N40: Superseded | O40: On GitHub default branch | P40: % completed | Q40: Avg completion % (where recorded)
A41: ATIP-DEV | B41: ATIP | C41: =COUNTIFS($B$5:$B$37,$B41) -> 13 | G41: =SUMIFS(G$5:G$37,$B$5:$B$37,$B41) -> 337 | H41: =SUMIFS(H$5:H$37,$B$5:$B$37,$B41) -> 130 | I41: =SUMIFS(I$5:I$37,$B$5:$B$37,$B41) -> 197 | J41: =SUMIFS(J$5:J$37,$B$5:$B$37,$B41) -> 9 | K41: =SUMIFS(K$5:K$37,$B$5:$B$37,$B41) -> 1 | L41: =SUMIFS(L$5:L$37,$B$5:$B$37,$B41) -> 0 | M41: =SUMIFS(M$5:M$37,$B$5:$B$37,$B41) -> 0 | N41: =SUMIFS(N$5:N$37,$B$5:$B$37,$B41) -> 0 | O41: =SUMIFS(O$5:O$37,$B$5:$B$37,$B41) -> 337 | P41: =IFERROR((H41+N41)/G41,0) -> 0.38575668 | Q41: =IFERROR(AVERAGEIFS('All Features'!$Q$2:$Q$423,'All Features'!$B$2:$B$423,$B41),"") -> 0.81197605
A42: bkesari | B42: Milk & Dairy marketplace | C42: =COUNTIFS($B$5:$B$37,$B42) -> 6 | G42: =SUMIFS(G$5:G$37,$B$5:$B$37,$B42) -> 33 | H42: =SUMIFS(H$5:H$37,$B$5:$B$37,$B42) -> 32 | I42: =SUMIFS(I$5:I$37,$B$5:$B$37,$B42) -> 0 | J42: =SUMIFS(J$5:J$37,$B$5:$B$37,$B42) -> 0 | K42: =SUMIFS(K$5:K$37,$B$5:$B$37,$B42) -> 0 | L42: =SUMIFS(L$5:L$37,$B$5:$B$37,$B42) -> 1 | M42: =SUMIFS(M$5:M$37,$B$5:$B$37,$B42) -> 0 | N42: =SUMIFS(N$5:N$37,$B$5:$B$37,$B42) -> 0 | O42: =SUMIFS(O$5:O$37,$B$5:$B$37,$B42) -> 32 | P42: =IFERROR((H42+N42)/G42,0) -> 0.96969697 | Q42: =IFERROR(AVERAGEIFS('All Features'!$Q$2:$Q$423,'All Features'!$B$2:$B$423,$B42),"") -> 1
A43: bkesari-platform | B43: Portal (bkesari.com hub) | C43: =COUNTIFS($B$5:$B$37,$B43) -> 4 | G43: =SUMIFS(G$5:G$37,$B$5:$B$37,$B43) -> 21 | H43: =SUMIFS(H$5:H$37,$B$5:$B$37,$B43) -> 19 | I43: =SUMIFS(I$5:I$37,$B$5:$B$37,$B43) -> 0 | J43: =SUMIFS(J$5:J$37,$B$5:$B$37,$B43) -> 0 | K43: =SUMIFS(K$5:K$37,$B$5:$B$37,$B43) -> 0 | L43: =SUMIFS(L$5:L$37,$B$5:$B$37,$B43) -> 1 | M43: =SUMIFS(M$5:M$37,$B$5:$B$37,$B43) -> 0 | N43: =SUMIFS(N$5:N$37,$B$5:$B$37,$B43) -> 1 | O43: =SUMIFS(O$5:O$37,$B$5:$B$37,$B43) -> 20 | P43: =IFERROR((H43+N43)/G43,0) -> 0.95238095 | Q43: =IFERROR(AVERAGEIFS('All Features'!$Q$2:$Q$423,'All Features'!$B$2:$B$423,$B43),"") -> 1
A44: bkesari-platform | B44: Education | C44: =COUNTIFS($B$5:$B$37,$B44) -> 10 | G44: =SUMIFS(G$5:G$37,$B$5:$B$37,$B44) -> 31 | H44: =SUMIFS(H$5:H$37,$B$5:$B$37,$B44) -> 19 | I44: =SUMIFS(I$5:I$37,$B$5:$B$37,$B44) -> 0 | J44: =SUMIFS(J$5:J$37,$B$5:$B$37,$B44) -> 0 | K44: =SUMIFS(K$5:K$37,$B$5:$B$37,$B44) -> 0 | L44: =SUMIFS(L$5:L$37,$B$5:$B$37,$B44) -> 0 | M44: =SUMIFS(M$5:M$37,$B$5:$B$37,$B44) -> 12 | N44: =SUMIFS(N$5:N$37,$B$5:$B$37,$B44) -> 0 | O44: =SUMIFS(O$5:O$37,$B$5:$B$37,$B44) -> 19 | P44: =IFERROR((H44+N44)/G44,0) -> 0.61290323 | Q44: =IFERROR(AVERAGEIFS('All Features'!$Q$2:$Q$423,'All Features'!$B$2:$B$423,$B44),"") -> 0.61290323
B45: ALL | G45: =SUM(G41:G44) -> 422 | H45: =SUM(H41:H44) -> 200 | I45: =SUM(I41:I44) -> 197 | J45: =SUM(J41:J44) -> 9 | K45: =SUM(K41:K44) -> 1 | L45: =SUM(L41:L44) -> 2 | M45: =SUM(M41:M44) -> 12 | N45: =SUM(N41:N44) -> 1 | O45: =SUM(O41:O44) -> 408 | P45: =IFERROR((H45+N45)/G45,0) -> 0.47630332
B46: Check: phase totals match 'All Features' | G46: =IF(AND(G45=COUNTA('All Features'!$F$2:$F$423),SUM(H45:N45)=G45),"OK","MISMATCH") -> OK

Sheet All Features
A1: Repo | B1: App | C1: Phase # | D1: Phase | E1: Area | F1: Feature ID | G1: Feature | H1: Details | I1: Delivered by | J1: Date | K1: Branch | L1: On GitHub default branch? | M1: GitHub status | N1: Local Git (fresh clone) | O1: Status | P1: Testing status | Q1: Completion % | R1: Blocker / next action | S1: Link
A2: ATIP-DEV | B2: ATIP | C2: 0 | D2: Phase 0: Delivered baseline (maintain) | E2: Data Platform | F2: DP-02 | G2: Daily OHLCV history | H2: NSE Bhavcopy + Dhan; coverage/freshness/duplicate guards | I2: Tracker wave 2 | J2: 46289 | K2: master | L2: Yes | M2: Merged to master | N2: In local master | O2: COMPLETED | P2: IN PROGRESS | Q2: 0.9 | R2: Maintain | S2: https://github.com/sanjaymorankar-debug/ATIP-DEV/blob/master/docs/ATIP_MASTER_TRACKER.csv
A3: ATIP-DEV | B3: ATIP | C3: 0 | D3: Phase 0: Delivered baseline (maintain) | E3: Data Platform | F3: DP-07 | G3: Delivery data | H3: Full Bhavcopy nightly + backfill | I3: Tracker wave 2 | J3: 46289 | K3: master | L3: Yes | M3: Merged to master | N3: In local master | O3: COMPLETED | P3: COMPLETED | Q3: 0.9 | R3: Maintain | S3: https://github.com/sanjaymorankar-debug/ATIP-DEV/blob/master/docs/ATIP_MASTER_TRACKER.csv
A4: ATIP-DEV | B4: ATIP | C4: 0 | D4: Phase 0: Delivered baseline (maintain) | E4: Data Platform | F4: DP-20 | G4: Trading calendar | H4: 2025-26 holidays + budget sessions | I4: Tracker wave 2 | J4: 46289 | K4: master | L4: Yes | M4: Merged to master | N4: In local master | O4: COMPLETED | P4: COMPLETED | Q4: 0.9 | R4: Add next year's holidays each December | S4: https://github.com/sanjaymorankar-debug/ATIP-DEV/blob/master/docs/ATIP_MASTER_TRACKER.csv
A5: ATIP-DEV | B5: ATIP | C5: 0 | D5: Phase 0: Delivered baseline (maintain) | E5: Technical Analysis | F5: TA-01 | G5: Core indicators | H5: Computed and stored; MACD fixed and normalised | I5: Tracker wave 3 | J5: 46289 | K5: master | L5: Yes | M5: Merged to master | N5: In local master | O5: COMPLETED | P5: COMPLETED | Q5: 0.9 | R5: Maintain | S5: https://github.com/sanjaymorankar-debug/ATIP-DEV/blob/master/docs/ATIP_MASTER_TRACKER.csv
A6: ATIP-DEV | B6: ATIP | C6: 0 | D6: Phase 0: Delivered baseline (maintain) | E6: Technical Analysis | F6: TA-02 | G6: Extended oscillators | H6: Computed and stored | I6: Tracker wave 3 | J6: 46289 | K6: master | L6: Yes | M6: Merged to master | N6: In local master | O6: COMPLETED | P6: COMPLETED | Q6: 0.8 | R6: Maintain | S6: https://github.com/sanjaymorankar-debug/ATIP-DEV/blob/master/docs/ATIP_MASTER_TRACKER.csv
A7: ATIP-DEV | B7: ATIP | C7: 0 | D7: Phase 0: Delivered baseline (maintain) | E7: Technical Analysis | F7: TA-05 | G7: Fibonacci | H7: 52-week 23.6/38.2/50/61.8 levels; W39: swing-anchored Fibonacci (last two 5-bar pivots in 120 sessions, 38.2 / 50 / 61.8 levels, nearest level and distance) in technical_ext, shown in the stock panel | I7: Tracker wave 3 | J7: 46302 | K7: master | L7: Yes | M7: Merged to master | N7: In local master | O7: COMPLETED | P7: COMPLETED | Q7: 0.8 | R7: Independent QA | S7: https://github.com/sanjaymorankar-debug/ATIP-DEV/blob/master/docs/ATIP_MASTER_TRACKER.csv
A8: ATIP-DEV | B8: ATIP | C8: 0 | D8: Phase 0: Delivered baseline (maintain) | E8: Technical Analysis | F8: TA-07 | G8: Trend features | H8: Computed and stored | I8: Tracker wave 3 | J8: 46289 | K8: master | L8: Yes | M8: Merged to master | N8: In local master | O8: COMPLETED | P8: COMPLETED | Q8: 0.8 | R8: Maintain | S8: https://github.com/sanjaymorankar-debug/ATIP-DEV/blob/master/docs/ATIP_MASTER_TRACKER.csv
A9: ATIP-DEV | B9: ATIP | C9: 0 | D9: Phase 0: Delivered baseline (maintain) | E9: Technical Analysis | F9: TA-08 | G9: Relative strength | H9: 20-day RS with date-matched benchmark; W39 (TA-08b): 63 / 126-session RS vs the stock's sector index (NSE industry -> NIFTYIT / PHARMA / AUTO / FMCG / METAL / REALTY / ENERGY / BANK / PSUBANK, NIFTY50 fallback flagged) and percentile within the industry; display only | I9: Tracker wave 3 | J9: 46302 | K9: master | L9: Yes | M9: Merged to master | N9: In local master | O9: COMPLETED | P9: COMPLETED | Q9: 0.8 | R9: Independent QA; IC research before any score use | S9: https://github.com/sanjaymorankar-debug/ATIP-DEV/blob/master/docs/ATIP_MASTER_TRACKER.csv
A10: ATIP-DEV | B10: ATIP | C10: 0 | D10: Phase 0: Delivered baseline (maintain) | E10: Alpha/Factor Engine | F10: SC-03 | G10: RRI | H10: Implemented | I10: Tracker wave 4 | J10: 46289 | K10: master | L10: Yes | M10: Merged to master | N10: In local master | O10: COMPLETED | P10: COMPLETED | Q10: 0.75 | R10: Institutional input improves with SC-14 | S10: https://github.com/sanjaymorankar-debug/ATIP-DEV/blob/master/docs/ATIP_MASTER_TRACKER.csv
A11: ATIP-DEV | B11: ATIP | C11: 0 | D11: Phase 0: Delivered baseline (maintain) | E11: Alpha/Factor Engine | F11: SC-04 | G11: MRI | H11: Implemented; MACD corrected | I11: Tracker wave 4 | J11: 46289 | K11: master | L11: Yes | M11: Merged to master | N11: In local master | O11: COMPLETED | P11: COMPLETED | Q11: 0.85 | R11: Maintain | S11: https://github.com/sanjaymorankar-debug/ATIP-DEV/blob/master/docs/ATIP_MASTER_TRACKER.csv
A12: ATIP-DEV | B12: ATIP | C12: 0 | D12: Phase 0: Delivered baseline (maintain) | E12: Alpha/Factor Engine | F12: SC-07 | G12: ZPI | H12: Implemented + delivery component | I12: Tracker wave 4 | J12: 46289 | K12: master | L12: Yes | M12: Merged to master | N12: In local master | O12: COMPLETED | P12: COMPLETED | Q12: 0.8 | R12: Maintain | S12: https://github.com/sanjaymorankar-debug/ATIP-DEV/blob/master/docs/ATIP_MASTER_TRACKER.csv
A13: ATIP-DEV | B13: ATIP | C13: 0 | D13: Phase 0: Delivered baseline (maintain) | E13: Alpha/Factor Engine | F13: SC-10 | G13: Portfolio Health score | H13: Implemented | I13: Tracker wave 4 | J13: 46289 | K13: master | L13: Yes | M13: Merged to master | N13: In local master | O13: COMPLETED | P13: IN PROGRESS | Q13: 0.75 | R13: Correlation/drawdown inputs come with PF-09 and PF-13 | S13: https://github.com/sanjaymorankar-debug/ATIP-DEV/blob/master/docs/ATIP_MASTER_TRACKER.csv
... A332: ATIP-DEV | B332: ATIP | C332: 11 | D332: Phase 11: W39 reconciliation (owner tracker 2026-10-07) | E332: Wealth / Mutual funds | F332: W39B-MFA | G332: Mutual fund analytics on stored AMFI NAVs (read-only) | H332: data/mf_analytics.py: point-to-point and CAGR returns, 1Y / 3Y rolling returns with hurdle stats, volatility / Sharpe / Sortino, drawdown with dates, beta / alpha / tracking error vs a price index, SIP and lump-sum XIRR, category rank among stored schemes, side-by-side compare; 3 read-only GET routes; scheme detail card on /data-platform | I332: W39b (PR #5) | J332: 46302 | K332: master | L332: Yes | M332: Merged to master | N332: In local master | O332: IMPLEMENTED BUT NOT VERIFIED | P332: COMPLETED | Q332: 0.85 | R332: Independent QA. Holding MFs in the wealth ledger stays out of scope (owner Scope Exclusions); benchmark is a price index, not total return; peers limited to stored schemes | S332: https://github.com/sanjaymorankar-debug/ATIP-DEV/blob/master/docs/ATIP_MASTER_TRACKER.csv
A333: ATIP-DEV | B333: ATIP | C333: 12 | D333: Phase 12: Platform: macOS and MySQL / PostgreSQL (PRs #1-#8) | E333: Database (MySQL) | F333: PR8-MYSQL | G333: MySQL runtime switch | H333: Translates the SQL constructs MySQL rejects (CAST, derived tables, self-reference), quotes MySQL-reserved column names (a test now keeps it at zero), fixes the two upserts that broke, pins the MySQL session time zone. SQLite stays the default; MySQL stays behind allow_experimental. | I333: PR #8 | J333: 46303 | K333: claude/awesome-dijkstra-fmccpl | L333: Yes | M333: Merged to master | N333: In local master | O333: COMPLETED | P333: PASS - full suite 1,336 passed (CI green) | R333: - | S333: https://github.com/sanjaymorankar-debug/ATIP-DEV/pull/8
A334: ATIP-DEV | B334: ATIP | C334: 12 | D334: Phase 12: Platform: macOS and MySQL / PostgreSQL (PRs #1-#8) | E334: macOS | F334: PF-1 | G334: Run ATIP on macOS | H334: start_atip.sh, LaunchAgents for the platform, the 5-minute snapshot upload and the daily Dhan token refresh; paths resolved from the script's own location | I334: PR #1 | J334: 46298 | K334: master | L334: Yes | M334: Merged to master | N334: In local master | O334: IMPLEMENTED BUT NOT VERIFIED | P334: PASS - full suite 1,336 passed (CI green) | R334: Owner check on the Mac | S334: https://github.com/sanjaymorankar-debug/ATIP-DEV/pull/1
A335: ATIP-DEV | B335: ATIP | C335: 12 | D335: Phase 12: Platform: macOS and MySQL / PostgreSQL (PRs #1-#8) | E335: Database | F335: PF-1 | G335: MySQL and PostgreSQL backends, data migration, serving at /ATIP/ | H335: db.mysql / db.postgres translation layers, tools/sqlite_to_mysql.py and sqlite_to_postgres.py, ATIP_ROOT_PATH for serving under /ATIP/ | I335: PR #1, #3 | J335: 46302 | K335: master | L335: Yes | M335: Merged to master | N335: In local master | O335: IMPLEMENTED BUT NOT VERIFIED | P335: PASS - full suite 1,336 passed (CI green) | R335: Owner check on the Mac | S335: https://github.com/sanjaymorankar-debug/ATIP-DEV/pull/1
A336: ATIP-DEV | B336: ATIP | C336: 12 | D336: Phase 12: Platform: macOS and MySQL / PostgreSQL (PRs #1-#8) | E336: Database | F336: PF-2 | G336: Schema scripts for a fresh database | H336: db/sql: SQLite, PostgreSQL and MySQL scripts generated from db.schema, verified against real servers | I336: PR #2 | J336: 46298 | K336: master | L336: Yes | M336: Merged to master | N336: In local master | O336: COMPLETED | P336: PASS - full suite 1,336 passed (CI green) | Q336: 1 | R336: - | S336: https://github.com/sanjaymorankar-debug/ATIP-DEV/pull/2
A337: ATIP-DEV | B337: ATIP | C337: 12 | D337: Phase 12: Platform: macOS and MySQL / PostgreSQL (PRs #1-#8) | E337: Database | F337: PF-6 | G337: --init reports the database it built | H337: main.py --init names the backend and database it actually created instead of always a SQLite path | I337: PR #6 | J337: 46302 | K337: master | L337: Yes | M337: Merged to master | N337: In local master | O337: COMPLETED | P337: PASS - full suite 1,336 passed (CI green) | Q337: 1 | R337: - | S337: https://github.com/sanjaymorankar-debug/ATIP-DEV/pull/6
A338: ATIP-DEV | B338: ATIP | C338: 12 | D338: Phase 12: Platform: macOS and MySQL / PostgreSQL (PRs #1-#8) | E338: Docs | F338: PF-7 | G338: Mac setup notes in the README | H338: Python 3.11+ from Homebrew, .env for the API key, Documents privacy, iCloud, sleep and time-zone checks | I338: PR #7 | J338: 46302 | K338: master | L338: Yes | M338: Merged to master | N338: In local master | O338: COMPLETED | P338: PASS - full suite 1,336 passed (CI green) | Q338: 1 | R338: - | S338: https://github.com/sanjaymorankar-debug/ATIP-DEV/pull/7
A339: bkesari | B339: Milk & Dairy marketplace | C339: 1 | D339: Phase 1: Core marketplace (19 Aug, PRs #1-#5) | E339: Website | F339: BK-01 | G339: Landing page and custom domain | H339: Placeholder landing page and CNAME for bkesari.com | I339: PR #2, #3 | J339: 46253 | K339: main | L339: Yes | M339: Merged to main | N339: In local main | O339: COMPLETED | P339: No dedicated test | Q339: 1 | R339: - | S339: https://github.com/sanjaymorankar-debug/bkesari/pull/2
A340: bkesari | B340: Milk & Dairy marketplace | C340: 1 | D340: Phase 1: Core marketplace (19 Aug, PRs #1-#5) | E340: Platform | F340: BK-02 | G340: Marketplace app foundation | H340: Next.js 16, React 19, TypeScript, Tailwind v4, Drizzle ORM (PostgreSQL at first, MySQL since PR #9), Auth.js (Google OAuth; email-only sign-in in development) | I340: PR #4 | J340: 46253 | K340: main | L340: Yes | M340: Merged to main | N340: In local main | O340: COMPLETED | P340: PASS - Automated tests: authorization.test.ts, acceptance.spec.ts (E2E) | Q340: 1 | R340: - | S340: https://github.com/sanjaymorankar-debug/bkesari/pull/4
A341: bkesari | B341: Milk & Dairy marketplace | C341: 1 | D341: Phase 1: Core marketplace (19 Aug, PRs #1-#5) | E341: Catalogue | F341: BK-03 | G341: Catalogue and shop browsing | H341: Home, Dairy, Bakery, Shops, shop page, search; seed with 5 demo shops, 18 categories, 40 products | I341: PR #4 | J341: 46253 | K341: main | L341: Yes | M341: Merged to main | N341: In local main | O341: COMPLETED | P341: PASS - Automated tests: acceptance.spec.ts (E2E) | Q341: 1 | R341: - | S341: https://github.com/sanjaymorankar-debug/bkesari/pull/4
A342: bkesari | B342: Milk & Dairy marketplace | C342: 1 | D342: Phase 1: Core marketplace (19 Aug, PRs #1-#5) | E342: Catalogue | F342: BK-04 | G342: Online / offline product control | H342: A product is purchasable online only if shop APPROVED, offering active, online enabled, online price set and stock suffices; enforced server-side and by DB CHECK constraints | I342: PR #4 | J342: 46253 | K342: main | L342: Yes | M342: Merged to main | N342: In local main | O342: COMPLETED | P342: PASS - Automated tests: checkout.test.ts | Q342: 1 | R342: - | S342: https://github.com/sanjaymorankar-debug/bkesari/pull/4
A343: bkesari | B343: Milk & Dairy marketplace | C343: 1 | D343: Phase 1: Core marketplace (19 Aug, PRs #1-#5) | E343: Shops | F343: BK-05 | G343: Kesari / Green shop classification | H343: Operator/admin-only classification; shop owners cannot change their own; every change audited | I343: PR #4 | J343: 46253 | K343: main | L343: Yes | M343: Merged to main | N343: In local main | O343: COMPLETED | P343: PASS - Automated tests: authorization.test.ts | Q343: 1 | R343: - | S343: https://github.com/sanjaymorankar-debug/bkesari/pull/4
A344: bkesari | B344: Milk & Dairy marketplace | C344: 1 | D344: Phase 1: Core marketplace (19 Aug, PRs #1-#5) | E344: Orders | F344: BK-06 | G344: Cart and checkout | H344: Server-validated cart, checkout from wallet, order lines snapshot name and price | I344: PR #4 | J344: 46253 | K344: main | L344: Yes | M344: Merged to main | N344: In local main | O344: COMPLETED | P344: PASS - Automated tests: checkout.test.ts | Q344: 1 | R344: - | S344: https://github.com/sanjaymorankar-debug/bkesari/pull/4
A345: bkesari | B345: Milk & Dairy marketplace | C345: 1 | D345: Phase 1: Core marketplace (19 Aug, PRs #1-#5) | E345: Wallet | F345: BK-07 | G345: Wallet with append-only ledger | H345: Integer paise, concurrency-safe debits, overdraw impossible, replay-safe operations, self-verifying ledger | I345: PR #4 | J345: 46253 | K345: main | L345: Yes | M345: Merged to main | N345: In local main | O345: COMPLETED | P345: PASS - Automated tests: wallet.test.ts | Q345: 1 | R345: - | S345: https://github.com/sanjaymorankar-debug/bkesari/pull/4
A346: bkesari | B346: Milk & Dairy marketplace | C346: 1 | D346: Phase 1: Core marketplace (19 Aug, PRs #1-#5) | E346: Subscriptions | F346: BK-08 | G346: Daily subscription engine | H346: Weekly schedule, pause, skip, per-date override, retry after top-up, calendar; idempotent daily-order cron (/api/cron/daily-orders) | I346: PR #4 | J346: 46253 | K346: main | L346: Yes | M346: Merged to main | N346: In local main | O346: COMPLETED | P346: PASS - Automated tests: subscription-engine.test.ts, schedule.test.ts | Q346: 1 | R346: Schedule the cron once daily on the host (DEPLOYMENT.md section 5) | S346: https://github.com/sanjaymorankar-debug/bkesari/pull/4
A347: bkesari | B347: Milk & Dairy marketplace | C347: 1 | D347: Phase 1: Core marketplace (19 Aug, PRs #1-#5) | E347: Admin | F347: BK-09 | G347: Shop registration, approval and dashboards | H347: Shop registration, operator approve/reject, operator and admin dashboards, notifications, audit log of sensitive mutations | I347: PR #4 | J347: 46253 | K347: main | L347: Yes | M347: Merged to main | N347: In local main | O347: COMPLETED | P347: PASS - Automated tests: authorization.test.ts | Q347: 1 | R347: - | S347: https://github.com/sanjaymorankar-debug/bkesari/pull/4
... A370: bkesari | B370: Milk & Dairy marketplace | C370: 6 | D370: Phase 6: MySQL and the bkesari.com hub (8-9 Oct, PRs #9, #10, #12, #13) | E370: Admin | F370: BK-32 | G370: Admin dashboard works on MySQL; migrate reads DB_* settings | H370: Two PostgreSQL ::bigint casts left in src/app/admin/page.tsx made /admin answer 500 on MySQL; db:migrate now builds its URL from DB_* like the app; README brought to MySQL. Opened by another session | I370: PR #12 | J370: 46303 | K370: claude/charming-edison-ofoncf | L370: Yes | M370: Merged to main | N370: In local main | O370: COMPLETED | P370: PASS - 284/284 on MySQL, also with a .env copied from .env.example (CI green) | Q370: 1 | R370: - | S370: https://github.com/sanjaymorankar-debug/bkesari/pull/12
A371: bkesari | B371: Milk & Dairy marketplace | C371: 6 | D371: Phase 6: MySQL and the bkesari.com hub (8-9 Oct, PRs #9, #10, #12, #13) | E371: Testing | F371: BK-33 | G371: Test database gets its own migrate command | H371: npm run db:migrate:test applies the schema to TEST_DATABASE_URL from .env, instead of a bash-only DATABASE_URL=... prefix. Opened by another session on 2026-10-09 | I371: PR #14 | J371: 46303 | K371: claude/awesome-dijkstra-fmccpl | L371: No | M371: Open PR - not merged | N371: Only on branch claude/awesome-dijkstra-fmccpl | O371: IN REVIEW (open PR) | P371: Its author reports 284/284 on MySQL 8.0; not re-run here | R371: Review, then merge or close PR #14 | S371: https://github.com/sanjaymorankar-debug/bkesari/pull/14
A372: bkesari-platform | B372: Portal (bkesari.com hub) | C372: 1 | D372: Phase 1: Portal and Task Tracker (16 Sep) | E372: Portal | F372: PL-01 | G372: Welcome portal with site menu | H372: bkesari.com landing page; menu picks test or production links from the address it is opened on | I372: commits 8f5356b, f88b45e | J372: 46281 | K372: main | L372: Yes | M372: Merged to main | N372: In local main | O372: COMPLETED | P372: PASS - 44 tests + 32 guard checks; Task Tracker saves to MySQL | Q372: 1 | R372: - | S372: https://github.com/sanjaymorankar-debug/bkesari-platform/commit/8f5356b
A373: bkesari-platform | B373: Portal (bkesari.com hub) | C373: 1 | D373: Phase 1: Portal and Task Tracker (16 Sep) | E373: Portal | F373: PL-02 | G373: Task Tracker (/tasks/) | H373: Projects and tasks with owner, status, planned/actual dates, current/next step, timestamped status updates, dashboard counts, overdue flag, search and filter; login-protected | I373: commit 8f5356b | J373: 46281 | K373: main | L373: Yes | M373: Merged to main | N373: In local main | O373: COMPLETED | P373: PASS - 44 tests + 32 guard checks; Task Tracker saves to MySQL | Q373: 1 | R373: Set TRACKER_USER / TRACKER_PASSWORD | S373: https://github.com/sanjaymorankar-debug/bkesari-platform/commit/8f5356b
A374: bkesari-platform | B374: Portal (bkesari.com hub) | C374: 1 | D374: Phase 1: Portal and Task Tracker (16 Sep) | E374: Portal | F374: PL-03 | G374: ATIP read-only viewer (/atip/) | H374: Token-protected snapshot upload from your PC, login-protected viewer, order buttons hidden, CSP blocks all network calls | I374: commits 4e864ef, f88b45e | J374: 46281 | K374: main | L374: Yes | M374: Merged to main | N374: In local main | O374: COMPLETED | P374: PASS - 44 tests + 32 guard checks; Task Tracker saves to MySQL | Q374: 1 | R374: Set ATIP_USER / ATIP_PASSWORD / ATIP_PUBLISH_TOKEN | S374: https://github.com/sanjaymorankar-debug/bkesari-platform/commit/4e864ef
A375: bkesari-platform | B375: Portal (bkesari.com hub) | C375: 1 | D375: Phase 1: Portal and Task Tracker (16 Sep) | E375: Portal | F375: PL-04 | G375: MySQL / SQLite database adapter | H375: Same SQL on MySQL (Hostinger) and SQLite (local, node:sqlite, Node 22.13+) | I375: commit 8f5356b | J375: 46281 | K375: main | L375: Yes | M375: Merged to main | N375: In local main | O375: COMPLETED | P375: PASS - 44 tests + 32 guard checks; Task Tracker saves to MySQL | Q375: 1 | R375: - | S375: https://github.com/sanjaymorankar-debug/bkesari-platform/commit/8f5356b
